Workbook

Sheet MAIO
A1: MAIO
A2: DATA DA TRANS. | B2: VIGÊNCIA | C2: SEGURADO | D2: QNT. DE PARCELAS | E2: SEGURADORA | F2: % COMISSÃO | G2: VALOR DA COMISSÃO
A3: 41758 | B3: 42123 | C3: ADILSON VENCESLAU | D3: 10X | E3: AZUL | F3: 0.1 | G3: 138.67
A4: 41759 | B4: 42126 | C4: HUMBERTO ANTONIO BARONI | D4: 10X | E4: MARITIMA | F4: 0.1 | G4: 107.25
A5: 41764 | B5: 40308 | C5: BRUNO FELLIPE DA CRUZ | D5: 4X | E5: BRADESCO | F5: 0.1 | G5: 158.58
A6: 41765 | B6: 42130 | C6: ERIKA GOMES DE LIMA | D6: 10X | E6: MITSUI | F6: 0.1 | G6: 174.42
A7: 41766 | B7: 42131 | C7: CRYSTIAN FELIX | D7: 10X | E7: TOKIO | F7: 0.25 | G7: 572.21
A8: 41767 | B8: 42133 | C8: MARCOS JOSE DA SILVA | D8: 5X | E8: PORTO | F8: 0.1 | G8: 102.12
A9: 41772 | B9: 42136 | C9: MARIA DE LOURDES LIMA DOS SANTOS | D9: 10X | E9: AZUL | F9: 0.1 | G9: 187.43
A10: 41773 | B10: 42138 | C10: FERNANDO ANTONIO DE OLIVEIRA | D10: 1X | E10: PORTO | F10: 0.2 | G10: 891.89
A11: 41774 | B11: 42145 | C11: EMERSON AMARINHO DE ARAÚJO | D11: 4X | E11: AZUL | F11: 0.1 | G11: 141.31
A12: 41775 | B12: 42137 | C12: HUGO LIMA | D12: 5X | E12: PORTO | F12: 0.18 | G12: 173.75
A13: 41775 | B13: 42144 | C13: AILSON PONTES DA SILVA | D13: 4X | E13: HDI | F13: 0.1 | G13: 285.34
A14: 41779 | B14: 42151 | C14: MARIZA DIAS AYRES MACHADO | D14: 4X | E14: AZUL | F14: 0.15 | G14: 202.6
... A21: 41788 | B21: 42153 | C21: REINALDO NONATO DA SILVA | D21: 1X | E21: HDI | F21: 0.2 | G21: 240.61
A24: VALOR TOTAL: | G24: =SUM(G3:G23) -> 4581.58

Sheet JUNHO
A1: JUNHO
A2: DATA DA TRANS. | B2: VIGÊNCIA | C2: SEGURADO | D2: QNT. DE PARCELAS | E2: SEGURADORA | F2: % COMISSÃO | G2: VALOR DA COMISSÃO
A3: 41794 | B3: 42159 | C3: WILSON DE SOUZA | D3: 1X | E3: MITSUI | F3: 0.15 | G3: 190.13
A4: 41794 | B4: 42159 | C4: JOSE ADENOR DA SILVA | D4: 10X | E4: MITSUI | F4: 0.11 | G4: 134.27
A5: 41795 | B5: 42157 | C5: PAULA REGINA BOTARO | D5: 4X | E5: AZUL | F5: 0.1 | G5: 203.93
A6: 41795 | B6: 42160 | C6: MARCIO ANDRE ALVES DOS SANTOS | D6: 10X | E6: LIBERTY | F6: 0.1 | G6: 265.2
A7: 41796 | B7: 42167 | C7: JOSE GERALDO DE MOREIRA | D7: 4X | E7: AZUL | F7: 0.19 | G7: 245.04
A8: 41801 | B8: 42168 | C8: GESIMARA DA COSTA MENDES | D8: 7X | E8: MITSUI | F8: 0.1 | G8: 113.87
A9: 41801 | B9: 42169 | C9: EMMANUEL MARTINS DE ALBUQUERQUE | D9: 1X | E9: TOKIO | F9: 0.1 | G9: 97.06
A10: 41801 | B10: 42167 | C10: GABRIELA GONÇALVES BRITO | D10: 4X | E10: AZUL | F10: 0.1 | G10: 81.65
A11: 41802 | B11: 42169 | C11: KELLY CRISTINA ACACIO VICENTE | D11: 4X | E11: BRADESCO | F11: 0.13 | G11: 149.71
A12: 41806 | B12: 42172 | C12: PAULO ALEXANDRE DA COSTA | D12: 10 | E12: MITSUI | F12: 0.1 | G12: 84.83
A13: 41807 | B13: 41808 | C13: ERICA MARIA GOMES DE LIMA | D13: 10X | E13: MITSUI | F13: 0.1 | G13: 203.54
A14: 41808 | B14: 41813 | C14: RYNALDO EDISON LEONARDO MARTINS ZAMAI | D14: 4X | E14: AZUL | F14: 0.15 | G14: 167.05
B15: 41814 | C15: THAIS DE FREITAS DOS SANTOS | D15: 4X | E15: AZUL | F15: 0.1 | G15: 98.99
B16: 41815 | C16: MICHELLE DOS SANTOS | D16: 5X | E16: SUL AMÉRICA | F16: 0.1 | G16: 150.46
B17: 41812 | C17: VALDEMAR DE SOUZA DA SILVA | D17: 10X | E17: MARÍTIMA | F17: 0.1 | G17: 82.02
B18: 41814 | C18: NELSON NUNES DA SILVA FILHO | D18: 6X | E18: TOKIO | F18: 0.1 | G18: 132.6
B19: 41810 | C19: GLEDISON DE PAULA BARBARA | D19: 4X | E19: AZUL | F19: 0.1 | G19: 108.87
B20: 41810 | C20: CARLOS LOPES REY | D20: 4X | E20: AZUL | F20: 0.25 | G20: 175.66
B21: 41803 | C21: FERNANDA MARTINS | D21: 10X | E21: MITSUI | F21: 0.1 | G21: 183.07
A23: VALOR TOTAL: | G23: =SUM(G3:G22) -> 2867.95

Sheet JULHO
A1: JULHO
A2: DATA DA TRANS. | B2: VIGÊNCIA | C2: SEGURADO | D2: QNT. DE PARCELAS | E2: SEGURADORA | F2: % COMISSÃO | G2: VALOR DA COMISSÃO
B3: 41822 | C3: FRANCISCO WESLEY ALVES ALMEIDA RUFINO | D3: 5X | E3: PORTO | F3: 0.25 | G3: 398.07
B4: 41822 | C4: JOSE ALVES ROCHA | D4: 4X | E4: AZUL | F4: 0.1 | G4: 100.23
B5: 41822 | C5: RENATO DE JESUS LINS | D5: 4X | E5: AZUL | F5: 0.1 | G5: 177.15
B6: 41825 | C6: FERNANDO SERGIO VIANA MACHADO | D6: 3X | E6: PORTO | F6: 0.25 | G6: 636.79
B7: 41823 | C7: MARIA GRAZIELA PEREIRA MELCHIOR VILLAR | D7: 4X | E7: LIBERTY | F7: 0.1 | G7: 225.65
B8: 41823 | C8: SUELI APARECIDA JORGE DE AZEVEDO | D8: 10X | E8: AZUL | F8: 0.1 | G8: 110.43
B9: 41828 | C9: CLAUDIA REGINA DIAS | D9: 4X | E9: PORTO | F9: 0.25 | G9: 220.77
C10: MARISA DIAS AYRES MACHADO | D10: 5X | E10: SUL AMERICA | F10: 0.15 | G10: 181.89
B11: 41830 | C11: LUCI GRUNOV | D11: 4X | E11: PORTO | F11: 0.2 | G11: 115.33
B12: 41827 | C12: ANSELMO DOS SANTOS UGARTE | D12: 4X | E12: AZUL | F12: 0.1 | G12: 118.53
B13: 41830 | C13: SEGMAX TECNOLOGIA EM ARGAMASSAS | D13: 7X | E13: HDI | F13: 0.25 | G13: 326
B14: 41830 | C14: RAIMUNDO NONATO NUNES | D14: 10X | E14: MITSUI | F14: 0.1735 | G14: 266.42
B15: 41835 | C15: ANGELO MARCIO ALVES NEVEZ | D15: 4X | E15: AZUL | F15: 0.1 | G15: 122.66
B16: 41839 | C16: NEUSA APARECIDA DE ARAUJO | D16: 5X | E16: SUL AMERICA | F16: 0.15 | G16: 347.21
B17: 41835 | C17: STARPACK | D17: 4X | E17: CHUBB | F17: 0.2 | G17: 377.56
B18: 41831 | C18: SERGIO RODRIGO BUENO | D18: 10X | E18: AZUL | F18: 0.1 | G18: 118.56
B19: 41844 | C19: IZAIAS MENDES DA SILVA | D19: 10X | E19: MITSUI | F19: 0.1 | G19: 71.28
B20: 41845 | C20: EDIVALDO PEREIRA DA SILVA | D20: 6X | E20: TOKIO | F20: 0.1 | G20: 111.16
B21: 41842 | C21: RAFAEL CUNHA DO NASCIMENTO | D21: 4X | E21: PORTO | F21: 0.15 | G21: 132.79
B22: 41842 | C22: FELIPE PENDEK | D22: 4X | E22: PORTO | F22: 0.1 | G22: 218.54
... B25: 41848 | C25: DALMO DE CARVALHO PONCIANO | D25: 4X | E25: TOKIO | F25: 0.1 | G25: 68.43
A26: VALOR TOTAL: | G26: =SUM(G3:G25) -> 4890.87

Sheet AGOSTO
A1: AGOSTO
A2: DATA DA TRANS. | B2: VIGÊNCIA | C2: SEGURADO | D2: QNT. DE PARCELAS | E2: SEGURADORA | F2: % COMISSÃO | G2: VALOR DA COMISSÃO | H2: COMISSÃO CORRETOR PREPOSTO
B3: 41860 | C3: PEDRO PAULO FARIA | D3: 4X | E3: MARÍTIMA | F3: 0.1 | G3: 83.97
B4: 41861 | C4: ALEXANDRE GOMIDE DE CASTRO | D4: 4X | E4: BRADESCO | F4: 0.1 | G4: 140.62
B5: 41863 | C5: GILBERTO ANDERRSON BRAZ | D5: 6X | E5: TOKIO | F5: 0.1 | G5: 142.39
B6: 41866 | C6: MAURICI AZEVEDO DO NASCIMENTO | D6: 5X | E6: PORTO | F6: 0.1 | G6: 204.36
B7: 41863 | C7: EVERALDO ALVES MAJOR | D7: 6X | E7: TOKIO | F7: 0.1 | G7: 159.9 | H7: 79.95 | I7: Mauro
B8: 41866 | C8: VALDEMIR SILVA ALMEIDA | D8: 10X | E8: MARÍTIMA | F8: 0.2 | G8: 211.12
B9: 41867 | C9: GEORGE ELIAS FERREIRA DA SILVA | D9: 2x | E9: HDI | F9: 0.1 | G9: 178.93
B10: 41871 | C10: MARCO AURELIO DA SILVA | D10: 10X | E10: AZUL | F10: 0.25 | G10: 289
B12: 41871 | C12: JOAO JUSTINO DOS SANTOS | D12: 6X | E12: TOKIO | F12: 0.1 | G12: 125.45
B13: 41873 | C13: MAURICIO MAURO MACHADO | D13: 4X | E13: AZUL | F13: 0.1 | G13: 135.89
B14: 41874 | C14: LEANDRO DE ALMEIDA CRISPIM ME | D14: 6X | E14: TOKIO | F14: 0.1 | G14: 204.53
B15: 41876 | C15: ROBERTA PRISCILA DA SILVA MATIAS | D15: 6X | E15: TOKIO | F15: 0.1 | G15: 72.22
B16: 41877 | C16: AQUINO IMOVEIS | D16: 4X | E16: AZUL | F16: 0.1 | G16: 99.45
B17: 41875 | C17: ADALBERTO SANTOS DE OLIVEIRA | D17: 10X | E17: PORTO | F17: 0.2 | G17: 374.4
B18: 41866 | C18: JEFFERSON D AMBROSIO DA CONCEI | D18: 11X | E18: PORTO | F18: 0.1 | G18: 163.08
B19: 41879 | C19: LUCIANO DA SILVA SENA | D19: 5X | E19: PORTO | F19: 0.25 | G19: 370.03
B20: 41880 | C20: DACIO LUIS DE CASTRO MENDES | D20: 7X | E20: HDI | F20: 0.15 | G20: 176.28
... B22: 41880 | C22: FRANCISCO ELEOTORIO CHAGAS JR | D22: 4X | E22: AZUL | F22: 0.15 | G22: 306.87
A24: VALOR TOTAL: | G24: =SUM(G3:G23) -> 3543.16

Sheet SETEMBRO
A1: SETEMBRO | H1: Preposto
A2: DATA DA TRANS. | B2: VIGÊNCIA | C2: SEGURADO | D2: QNT. DE PARCELAS | E2: SEGURADORA | F2: % COMISSÃO | G2: VALOR DA COMISSÃO
B3: 41885 | C3: LUCIENE TEREZA DA SILVA | D3: 5X | E3: AZUL | F3: 0.1 | G3: 123.55
B4: 41886 | C4: JEFFERSON RODRIGUES | D4: 4X | E4: BRADESCO | F4: 0.15 | G4: 291.13
B5: 41892 | C5: MICHELLE DOS SANTOS | D5: 4X | E5: HDI | F5: 0.1 | G5: 228.55
B6: 41891 | C6: CLEBER EDSON BANDEIRA | D6: 5X | E6: PORTO | F6: 0.25 | G6: 336.18
B7: 41892 | C7: SEGMAX TECNOLOGIA EM ARGAMASSAS | D7: 4X | E7: BRADESCO | F7: 0.15 | G7: 208.21
B8: 41901 | C8: GILBERTO RODRIGUES MAGUETA | D8: 4X | E8: MARÍTIMA | F8: 0.22 | G8: 198.72
B9: 41899 | C9: AKISHIDE YAMASHITA | D9: 1X | E9: PORTO | F9: 0.2 | G9: 222.26
B10: 41897 | C10: ALBA CELIA SOARES MOTA | D10: 10X | E10: SUL AMÉRICA | F10: 0.15 | G10: 197.47
B11: 41897 | C11: ADJAILSON PONTES DA SILVA | D11: 4X | E11: BRADESCO | F11: 0.1 | G11: 236.83
B12: 41895 | C12: LUCIANO DE LIMA ARAUJO | D12: 4X | E12: AZUL | F12: 0.1 | G12: 101.45
B13: 41898 | C13: JOSÉ MILTON REIS | D13: 1X | E13: MITSUI | F13: 0.2 | G13: 256.91
B14: 41900 | C14: REGINA CRISTINA LEITE PEREIRA | D14: 5X | E14: SUL AMÉRICA | F14: 0.1 | G14: 82.24
... B23: 41912 | C23: THAIS FERRE FAILLA | D23: 4X | E23: AZUL | F23: 0.1 | G23: 106.17
B24: 41911 | C24: RAPHAEL TREPICHIO | D24: 10X | E24: MITSUI | F24: 0.1 | G24: 135.95 | H24: Mauro
A25: VALOR TOTAL: | G25: =SUM(G3:G24) -> 4178.36

Sheet OUTUBRO
A1: OUTUBRO
A2: DATA DA TRANS. | B2: VIGÊNCIA | C2: SEGURADO | D2: QNT. DE PARCELAS | E2: SEGURADORA | F2: % COMISSÃO | G2: VALOR DA COMISSÃO
B3: 41917 | C3: SUEMARY LOPES DE BARROS | D3: 4X | E3: AZUL | F3: 0.1 | G3: 111
B4: 41923 | C4: JOSE DERNIVAL SANTOS FILHO | D4: 10X | E4: BRADESCO | F4: 0.1 | G4: 142.96
B5: 41924 | C5: MARCOS LEANDRO DA SILVA | D5: 6X | E5: TOKIO | F5: 0.2 | G5: 215.49
B6: 41926 | C6: JULIANA MAITAN BITTENCOURT | D6: 4X | E6: PORTO | F6: 0.1 | G6: 144.89
B7: 41922 | C7: LUCIANO DE OLIVEIRA MACEDO | D7: 6X | E7: MAPFRE | F7: 0.1 | G7: 188.53
B8: 41922 | C8: MARLUCE SANTOS MARTINS | D8: 6X | E8: TOKIO | F8: 0.1 | G8: 138.56
B9: 41923 | C9: ALEX GONÇALVES DE ANDRADE | D9: 4X | E9: AZUL | F9: 0.15 | G9: 224.94
B10: 41927 | C10: RICARDO JOSE DE VASCONCELOS | D10: 4X | E10: AZUL | F10: 0.1 | G10: 173.56
B11: 41932 | C11: PRISCILA MINGHETTI PERRUD | D11: 5X | E11: PORTO | F11: 0.1 | G11: 154.95
B12: 41913 | C12: FRANCISCO DAS CHAGAS F. DE LIMA | D12: 2X | E12: LIBERTY | F12: 0.1 | G12: 575.77
B13: 41938 | C13: WALTER PEREIRA DE ALMEIDA | D13: 10X | E13: AZUL | F13: 0.1 | G13: 83.16
B14: 41939 | C14: LUCIANO DA SILVA SENA | D14: 4X | E14: BRADESCO | F14: 0.1 | G14: 220.05
... B19: 41943 | C19: EDILENE ROSA DE ARAUJO | D19: 5X | E19: SUL AMÉRICA | F19: 0.1 | G19: 112.77
A24: VALOR TOTAL: | G24: =SUM(G3:G23) -> 3272.36

Sheet NOVEMBRO
A1: NOVEMBRO
A2: DATA DA TRANS. | B2: VIGÊNCIA | C2: SEGURADO | D2: QNT. DE PARCELAS | E2: SEGURADORA | F2: % COMISSÃO | G2: VALOR DA COMISSÃO | H2: PREPOSTO/ COMISSÕES
B3: 41946 | C3: LUANA DE CAIRES COELHO | D3: 4X | E3: HDI | F3: 17.50% | G3: 181.33
B4: 41946 | C4: JORGE LUIS MONTE DA SILVA | D4: 10X | E4: TOKIO | F4: 0.1 | G4: 118.64
B5: 41959 | C5: TARCISIO ANTONIO VALENTIM | D5: 1X | E5: PORTO | F5: 0.1 | G5: 128.37
B6: 41948 | C6: FERNANDA GONZALES DE LIMA | D6: 6X | E6: AZUL | F6: 0.15 | G6: 165.34
B7: 41949 | C7: PATRICIA DE ARAUJO NUNES | D7: 10X | E7: AZUL | F7: 0.15 | G7: 207.7
B8: 41954 | C8: ADEMIR CYRINO GARCIA | D8: 4X | E8: AZUL | F8: 0.2 | G8: 227.86
B9: 41950 | C9: ROSANA ARAKAKI GUIMARAES | D9: 5X | E9: PORTO | F9: 0.1 | G9: 295.32
B10: 41955 | C10: SEBASTIÃO MARCIO CAPELLO | D10: 4X | E10: AZUL | F10: 0.1 | G10: 92.87
B11: 41962 | C11: LUCIENE APARECIDA PANSARIN | D11: 4X | E11: AZUL | F11: 0.25 | G11: 217.83
B12: 41959 | C12: SEVERINO BERNARDO DA SILVA | D12: 4X | E12: MARITIMA | F12: 0.2 | G12: 169.66
B13: 41966 | C13: ADEMIR ROCHA GARCIA | D13: 7X | E13: AZUL | F13: 0.1 | G13: 140.66
B14: 41959 | C14: ROSEMEIRE PASSERE | D14: 10X | E14: AZUL | F14: 0.1 | G14: 144.2
B15: 41953 | C15: ALEX SANDRO BRAGARO | D15: 7X | E15: MITSUI | F15: 0.1 | G15: 125
B16: 41962 | C16: JOSE AUGUSTO GALAN | D16: 2X | E16: AZUL | F16: 0.2 | G16: 203.55
B17: 41969 | C17: ALEXANDRE GARCIA DA PAIXÃO | D17: 4X | E17: BRADESCO | F17: 0.1 | G17: 157.83 | H17: Mauro - R$ 78,91 - Pago
B18: 41965 | C18: FLAVIA RUBIA DE PAULA | D18: 4X | E18: AZUL | F18: 0.1 | G18: 137.71
B19: 41968 | C19: ESTANISLAU SEVERINO DE ARRUDA JUNIOR | D19: 5X | E19: SUL AMÉRICA | F19: 0.1 | G19: 101.56
B20: 41964 | C20: GILBERTO BRITO DA SILVA | D20: 4X | E20: MITSUI | F20: 0.1 | G20: 227.17
B21: 41971 | C21: ANDERSON SILVEIRO | D21: 10X | E21: MITSUI | F21: 0.1 | G21: 170.61
B22: 41968 | C22: ENOQUE RAIMUNDO DE OLIVEIRA | D22: 4X | E22: MARITIMA | F22: 0.1 | G22: 90.99
B23: 41971 | C23: VANESSA SALLUM CUNHA | D23: 1X | E23: MITSUI | F23: 0.1 | G23: 191.05 | H23: Mauro - R$ 95,52 Pago
B24: 41972 | C24: VANESSA DE CASTRO MENDES | D24: 4X | E24: BRADESCO | F24: 0.1 | G24: 125.44
A25: VALOR TOTAL: | G25: =SUM(G3:G24) -> 3620.69

Sheet DEZEMBRO
A1: DEZEMBRO | H1: PREPOSTOS
A2: DATA DA TRANS. | B2: VIGÊNCIA | C2: SEGURADO | D2: QNT. DE PARCELAS | E2: SEGURADORA | F2: % COMISSÃO | G2: VALOR DA COMISSÃO | H2: Prepostos/ Comissões
B3: 41974 | C3: ELISEU ALENCAR SANTIAGO | D3: 4X | E3: AZUL | F3: 0.15 | G3: 296.35 | H3: Vinicius/ 148,17 - Pago
B4: 41976 | C4: ALEXANDRA SEREICIKAS | D4: 4X | E4: HDI | F4: 0.25 | G4: 233.87
B5: 41977 | C5: DANIELA AVELINO CUNHA ANDRADE | D5: 4X | E5: HDI | F5: 0.2 | G5: 280.06
B6: 41975 | C6: ORLANDO BERNARDES FAUSTINO | D6: 4X | E6: PORTO | F6: 0.25 | G6: 262.7
B7: 41979 | C7: LUZIA BARBOSA | D7: 4X | E7: MARITIMA | F7: 0.1 | G7: 155.5
B8: 41982 | C8: ROBERTA PEREIRA DA PURIFICAÇÃO | D8: 4X | E8: HDI | F8: 0.1 | G8: 84.97 | H8: Mauro/ 42,48 - Pago
B9: 41984 | C9: LEANDRO CUNHA DE VASCONCELOS | D9: 10X | E9: MITSUI | F9: 0.1 | G9: 180.72 | H9: Mauro/ 90,36
B10: 41985 | C10: MARCELO PAULO DE OLIVEIRA | D10: 7X | E10: MITSUI | F10: 0.15 | G10: 328.27
B11: 41990 | C11: ADRIANO LOPES SANTOS | D11: 8X | E11: AZUL | F11: 0.14 | G11: 184.94 | H11: Mauro - 92,47
B12: 41987 | C12: ESTANISLAU SEVERINO DE ARRUDA JUNIOR | D12: 7X | E12: AZUL | F12: 0.1 | G12: 87.76
B13: 41987 | C13: TEGNUS FRANCISCUS LAMAS | D13: 7X | E13: MITSUI | F13: 0.17 | G13: 254.14
B14: 41982 | C14: ANA MARIA SOTERO | D14: 10X | E14: AZUL | F14: 0.1 | G14: 139.77
B15: 41989 | C15: ALAOR GONÇALVES DIAS | D15: 5X | E15: PORTO | F15: 0.1 | G15: 133.83
B16: 41990 | C16: ALEXANDRE ALFREDO LAMEIRÃO | D16: 4X | E16: AZUL | F16: 0.15 | G16: 191.25
B17: 41993 | C17: PAULO RAIMUNDO BAUEB | D17: 1X | E17: AZUL | F17: 0.1 | G17: 89.87
B18: 41996 | C18: SUELI GOMES DA SILVA JURAS | D18: 4X | E18: SUL AMÉRICA | F18: 0.1 | G18: 95.37
B19: 41996 | C19: ERICK DOMINGOS PELINSON QUIRINO | D19: 1X | E19: PORTO | F19: 0.1 | G19: 116.38
B20: 41997 | C20: ABELARDO MATIAS BACELAR | D20: 5X | E20: SUL AMÉRICA | F20: 0.24 | G20: 363.76
B21: 41996 | C21: SANDRA CRISTINA MENDES BOZZO | D21: 4x | E21: MARITIMA | F21: 0.2 | G21: 368.41 | H21: JORGE - R$ 184,20 - PAGO
B22: 42002 | C22: IVONE ALVES DE MELO | D22: 10X | E22: AZUL | F22: 0.1 | G22: 111.81
B23: 42003 | C23: RODRIGO GONÇALVES DA SILVA | D23: 10X | E23: AZUL | F23: 0.1 | G23: 102.45
A24: VALOR TOTAL: | G24: =SUM(G3:G23) -> 4062.18

Sheet JANEIRO
A1: DATA DA TRANS. | B1: VIGÊNCIA | C1: SEGURADO | D1: QNT. DE PARCELAS | E1: SEGURADORA | F1: % COMISSÃO | G1: VALOR DA COMISSÃO | H1: COMISSÕES
B2: 42006 | C2: OSVALDO GONÇALVES DE ALMEIDA | D2: 4X | E2: AZUL | F2: 0.1 | G2: 82.57
B3: 42009 | C3: ADRIANA M PEREIRA | D3: 1X | E3: AZUL | F3: 0.1 | G3: 156.55
B4: 42010 | C4: JEFFERSON D AMBROSIO DA CONCEIÇÃO | D4: 10X | E4: AZUL | F4: 0.15 | G4: 185.82
B5: 42012 | C5: ANTONIO CESAR ESTEVES | D5: 4X | E5: TOKIO | F5: 0.21 | G5: 324.62 | H5: JORGE - R$ 162,31 - PAGO
B6: 42013 | C6: CARLOS EDUARDO SILVA DE SOUZA | D6: 4X | E6: AZUL | F6: 0.19 | G6: 377
B7: 42013 | C7: KATIA REGINA DA SILVA | D7: 4X | E7: HDI | F7: 0.1 | G7: 104.47
B8: 42014 | C8: LUANA CARLA MARQUES | D8: 4X | E8: AZUL | F8: 0.2 | G8: 251.78
B9: 42016 | C9: CARLOS ALBERTO ROQUE SANTOS | D9: 10X | E9: SUL AMÉRICA | F9: 0.1 | G9: 113.1
B10: 42016 | C10: ROSANA CLAUDIA FAUSTINO | D10: 7X | E10: AZUL | F10: 0.1 | G10: 132.98
B11: 42020 | C11: MARCUS VINICIUS DE ARAUJO BATISTA | D11: 10X | E11: BRADESCO | F11: 0.18 | G11: 252.02
B12: 42028 | C12: NOZIOZENO BATISTA DOS SANTOS | D12: 4X | E12: AZUL | F12: 0.1 | G12: 143.17
B13: 42026 | C13: MIRIA CORREA PEREIRA ISRAEL | D13: 6X | E13: MAPFRE | F13: 0.1 | G13: 164.89
B14: 42029 | C14: NORBERTO DE SOUZA | D14: 4X | E14: BRADESCO | F14: 0.1 | G14: 146.36
B15: 42027 | C15: GEORGE ELIAS FERREIRA DA SILVA | D15: 4X | E15: AZUL | F15: 0.1 | G15: 196.73
B16: 42026 | C16: GEANE SALVIEIRO TEPERINO AVILA | D16: 6X | E16: TOKIO | F16: 0.1 | G16: 135.62
B17: 42031 | C17: FABIO FERNANDES COSTA | D17: 5X | E17: SUL AMÉRICA | F17: 0.1 | G17: 147.66
A18: VALOR TOTAL: | G18: =SUM(G2:G17) -> 2915.34

Sheet FEVEREIRO
A1: DATA DA TRANS. | B1: VIGÊNCIA | C1: SEGURADO | D1: QNT. DE PARCELAS | E1: SEGURADORA | F1: % COMISSÃO | G1: VALOR DA COMISSÃO | H1: COMISSÕES
A2: 42037 | B2: 42036 | C2: FRANCISCO JOSE MOREIRA | D2: 5X | E2: PORTO | F2: 0.1398 | G2: 372.4
B3: 42040 | C3: ADRINI CARLOS CORTEZ | D3: 4X | E3: AZUL | F3: 0.1 | G3: 137.67
A4: 42041 | B4: 42042 | C4: REGIANE RHEIN TORRES SOBRAL | D4: 10X | E4: TOKIO | F4: 0.1 | G4: 218.79
A5: 42044 | B5: 42044 | C5: MARIA RISALVA TAVARES | D5: 4X | E5: BRADESCO | F5: 0.1 | G5: 199.68
A6: 42046 | B6: 42047 | C6: LUCIANA APEZZATTO JOAQUIM U. | D6: 6X | E6: TOKIO | F6: 0.1 | G6: 121.51
B7: 42048 | C7: MARIA APARECIDA ALVES NOGUEIRA | D7: 1X | E7: AZUL | F7: 0.15 | G7: 257.73
B8: 42049 | C8: ELAINE CRISTINA DA SILVA | D8: 4X | E8: AZUL | F8: 0.1 | G8: 118.53
B9: 42049 | C9: MARIA APARECIDA DOMINGOS | D9: 4X | E9: AZUL | F9: 0.1 | G9: 138.27
A10: 42046 | B10: 42050 | C10: SILVIA VIEIRA BARRETO | D10: 10X | E10: MITSUI | F10: 0.25 | G10: 246.62
B11: 42050 | C11: MIRIAN RIBEIRO | D11: 6X | E11: TOKIO | F11: 0.1 | G11: 133.7
B12: 42052 | C12: MARCOS LEANDRO DA SILVA | D12: 4X | E12: HDI | F12: 0.15 | G12: 182.54
B13: 42052 | C13: KATIA REGINA DA SILVA | D13: 4X | E13: PORTO | F13: 0.1 | G13: 105.81
B14: 42053 | C14: CAIO BRUNO BALTAZAR | D14: 2X | E14: BRADESCO | F14: 0.1 | G14: 86.25
B15: 42054 | C15: ANTONIO SOARES DE CARVALHO | D15: 10 | E15: AZUL | F15: 0.12 | G15: 118.75
B16: 42056 | C16: VALDOMIRO PENDEK | D16: 4X | E16: PORTO | F16: 0.1 | G16: 170.75
B17: 42057 | C17: ANGELA DOS SANTOS CARVALHO | D17: 10X | E17: MITSUI | F17: 0.1 | G17: 146.21
B18: 42059 | C18: ALISSON GONÇALVES DA SILVA | D18: 5X | E18: SUL AMÉRICA | F18: 0.1 | G18: 220.13
A19: 42061 | B19: 42061 | C19: JOSÉ AMARO BATISTA | D19: 4X | E19: AZUL | F19: 0.1 | G19: 128.45
A20: VALOR TOTAL: | G20: =SUM(G2:G19) -> 3103.79

Sheet MARÇO
A1: DATA DA TRANS. | B1: VIGÊNCIA | C1: SEGURADO | D1: QNT. DE PARCELAS | E1: SEGURADORA | F1: % COMISSÃO | G1: VALOR DA COMISSÃO | H1: VALOR DA COMISSÃO
A2: 42065 | B2: 42064 | C2: LUCIANA PIERONI COUTINHO | D2: 1X | E2: PORTO | F2: 0.1 | G2: 156.51
A3: 42062 | B3: 42065 | C3: THIAGO TADEU DE LIMA | D3: 4X | E3: AZUL | F3: 0.1 | G3: 191.36
B4: 42065 | C4: MONIKA ELIZABETH JUNG MATRONI | D4: 6X | E4: MITSUI | F4: 0.15 | G4: 257.25 | H4: 128,62 - Mauro
A5: 42062 | B5: 42066 | C5: HUMBERTO MATIAS ALVES SILVA | D5: 4X | E5: MITSUI | F5: 0.2 | G5: 297.58
A6: 42061 | B6: 42066 | C6: MARCELA DALTO AMMIRABILE | D6: 1X | E6: AZUL | F6: 0.1 | G6: 139.5
A7: 42067 | B7: 42068 | C7: ROSENAIDE RITA FERREIRA O. COELHO | D7: 6X | E7: TOKIO | F7: 0.1 | G7: 166.54
A8: 42062 | B8: 42069 | C8: EDSON BATISTA DE MORAES | D8: 7x | E8: HDI | F8: 0.18 | G8: 241.71
A9: 42069 | B9: 42069 | C9: CARLOS ROGÉRIO GOMIDE | D9: 5X | E9: TOKIO | F9: 0.1 | G9: 126.18
A10: 42062 | B10: 42069 | C10: EDSON COSTA | D10: 4X | E10: AZUL | F10: 0.1 | G10: 119.24
A11: 42069 | B11: 42069 | C11: JOANA DARC JACINTO SOARES COELHO | D11: 6X | E11: MITSUI | F11: 0.1 | G11: 170.02
A12: 42069 | B12: 42073 | C12: CARLOS ALBERTO PINTO | D12: 4X | E12: AZUL | F12: 0.12 | G12: 118.23
A13: 42073 | B13: 42077 | C13: ADRIANA DA SILVA MONÇÃO BARROS | D13: 10X | E13: AZUL | F13: 0.23 | G13: 501.08
A14: 42075 | B14: 42077 | C14: JAILSON DE JESUS SANTOS | D14: 1X | E14: SUL AMÉRICA | F14: 0.23 | G14: 311.17
A15: 42075 | B15: 42078 | C15: VANDERLEI PEREIRA DE ALMEIDA | D15: 4X | E15: TOKIO | F15: 0.15 | G15: 203.49
A16: 42076 | B16: 42072 | C16: JAILSONPEREIRA DA SILVA | D16: 4X | E16: AZUL | F16: 0.1 | G16: 275.94
... A23: 42088 | B23: 42088 | C23: RENATA CARLA FAUSTINO DE MELO | D23: 4X | E23: AZUL | F23: 0.1 | G23: 204.19
A24: 42089 | B24: 42089 | C24: ADRIANA DOS SANTOS PEREIRA | D24: 10 | E24: MITSUI | F24: 0.1 | G24: 207.56
A25: 42089 | B25: 42089 | C25: PAULA REGINA BOTARO | D25: 6X | E25: TOKIO | F25: 0.1 | G25: 231.71
A26: 42090 | B26: 42090 | C26: FLAVIA APARECIDA MORAIS MARTINS | D26: 10X | E26: MITSUI | F26: 0.1 | G26: 222.62
A27: 42089 | B27: 42093 | C27: RITA DE CASSIA MENDES | D27: 4X | E27: MITSUI | F27: 0.1 | G27: 142.79
A28: VALOR TOTAL: | G28: =SUM(G2:G27) -> 5488

Sheet ABRIL
A1: DATA DA TRANS. | B1: VIGÊNCIA | C1: SEGURADO | D1: QNT. DE PARCELAS | E1: SEGURADORA | F1: % COMISSÃO | G1: VALOR DA COMISSÃO | H1: VALOR DA COMISSÃO
A2: 42096 | B2: 42096 | C2: FRANCISCO PAIVA DE FREITAS | D2: 4X | E2: TOKIO | F2: 0.1 | G2: 134.03
A3: 42095 | B3: 42096 | C3: JOHNNY BISPO DIAS | D3: 10X | E3: MITSUI | F3: 0.2 | G3: 179.82
A4: 42096 | B4: 42098 | C4: POLYANA DE PAULA ALBUQUERQUE | D4: 4X | E4: MAPFRE | F4: 0.1 | G4: 233.19
A5: 42102 | B5: 42102 | C5: JUCIELIA RODRIGUES DOS ANJOS | D5: 5X | E5: SUL AMÉRICA | F5: 0.1 | G5: 139.31
A6: 42104 | B6: 42104 | C6: BRUNA LISBOA TORRES SOBRAL | D6: 4X | E6: SUL AMÉRICA | F6: 0.2 | G6: 375.87
A7: 42104 | B7: 42104 | C7: RODRIGO CARRERAS DE OLIVEIRA MOTA | D7: 3X | E7: SUHAI | F7: 0.2 | G7: 293.49
A8: 42108 | B8: 42108 | C8: FERNANDO NONATO MARTINES | D8: 4X | E8: AZUL | F8: 0.1 | G8: 108
A9: 42109 | B9: 42109 | C9: ROSANA ARAKAKI GUIMARAES | D9: 4X | E9: SUL AMÉRICA | F9: 0.22 | G9: 305.88
A10: 42110 | B10: 42110 | C10: JOSE GERALDO RIBEIRO | D10: 5X | E10: MARITIMA | F10: 0.1 | G10: 155.1 | H10: Vinicius - 77,55
A11: 42110 | B11: 42110 | C11: EDUARDO GENOVESI FERNANDES | D11: 4X | E11: HDI | F11: 0.1 | G11: 321.45
A12: 42109 | B12: 42117 | C12: KARINA YUMI KATSUURA | D12: 1X | E12: MITSUI | F12: 0.1 | G12: 85.6
A13: 42116 | B13: 42116 | C13: RENATO LEITE RODRIGUES | D13: 3X | E13: SUL AMÉRICA | F13: 0.14 | G13: 276.96
A14: 42117 | B14: 42116 | C14: CICERO TERTO | D14: 4X | E14: TOKIO | F14: 0.1 | G14: 181.77
A15: 42118 | B15: 42118 | C15: ÁLVARO LUIZ MANCHON SARNES | D15: 4X | E15: SUL AMÉRICA | F15: 0.18 | G15: 237.47
A16: 42118 | B16: 42119 | C16: MARIO PAULO DA SILVA DOMINGOS | D16: 6X | E16: MAPFRE | F16: 0.1 | G16: 281.5
A17: 42122 | B17: 42122 | C17: ADJAILSON PONTES DA SILVA | D17: 5X | E17: SUL AMÉRICA | F17: 0.17 | G17: 396.05
A23: VALOR TOTAL: | G23: =SUM(G2:G22) -> 3705.49

Sheet MAIO 2015
A1: DATA DA TRANS. | B1: VIGÊNCIA | C1: SEGURADO | D1: QNT. DE PARCELAS | E1: SEGURADORA | F1: % COMISSÃO | G1: VALOR DA COMISSÃO | H1: COMISSÕES/CORRETORES
A2: 42123 | B2: 42126 | C2: HUMBERTO ANTONIO BARONI | D2: 10X | E2: TOKIO | F2: 0.1 | G2: 122.17
A3: 42121 | B3: 42130 | C3: ERICA MARIA GOMES DE LIMA | D3: 10X | E3: MITSUI | F3: 0.25 | G3: 435.89
A4: 42124 | B4: 42129 | C4: ADILSON VENCESLAU BRAS | D4: 10X | E4: AZUL | F4: 0.1 | G4: 125.79
A5: 42124 | B5: 42006 | C5: ROBERTO SELESTINO | D5: 4X | E5: MITSUI | F5: 0.1 | G5: 154.25 | H5: 77,12 - Mauro
A6: 42132 | B6: 42133 | C6: MARCOS JOSE DA SILVA | D6: 4X | E6: AZUL | F6: 0.1 | G6: 114.3
A7: 42137 | B7: 42137 | C7: HUGO LIMA | D7: 4X | E7: AZUL | F7: 0.1 | G7: 111.27
A8: 42138 | B8: 42138 | C8: FERNANDO ANTONIO DE OLIVEIRA | D8: 4X | E8: PORTO | F8: 0.1 | G8: 499.25
A9: 42138 | B9: 42138 | C9: GEORGE DE OLIVEIRA | D9: 3X | E9: PORTO | F9: 0.1 | G9: 211.59
A10: 42138 | B10: 42138 | C10: WALTER VINICIUS GUZMAN DE ALMEIDA | D10: 7X | E10: SUHAI | F10: 0.1 | G10: 147.64
A11: 42139 | B11: 42139 | C11: GERALDO AMARINHO DE ARAUJO | D11: 10X | E11: AZUL | F11: 0.1 | G11: 154.28
A12: 42142 | B12: 42145 | C12: EMERSON AMARINHO DE ARAUJO | D12: 4X | E12: AZUL | F12: 0.1 | G12: 160.86
A13: 42143 | B13: 42143 | C13: EVANDRO VILARONGA RIOS | D13: 8X | E13: AZUL | F13: 0.1 | G13: 160.19
A14: 42145 | B14: 42145 | C14: MARCIA LOPES DE SOUSA | D14: 2X | E14: AZUL | F14: 0.1 | G14: 140.3
A15: 42145 | B15: 42147 | C15: EVANDRO FERREIRA DA COSTA | D15: 6X | E15: TOKIO | F15: 0.15 | G15: 209.94
A16: 42149 | B16: 42149 | C16: SEVERINO MIGUEL DA SILVA | D16: 4X | E16: AZUL | F16: 0.25 | G16: 287.32
A17: 42151 | B17: 42151 | C17: RODRIGO GONÇALVES DA SILVA | D17: 6X | E17: TOKIO | F17: 0.15 | G17: 389.3
... A22: 42152 | B22: 42155 | C22: CAIO FELLIPE DA CRUZ | D22: 4X | E22: AZUL | F22: 0.2 | G22: 422.87
A23: VALOR TOTAL: | G23: =SUM(G2:G22) -> 4403.26

Sheet JUNHO 2015
A1: DATA DA TRANS. | B1: VIGÊNCIA | C1: SEGURADO | D1: QNT. DE PARCELAS | E1: SEGURADORA | F1: % COMISSÃO | G1: VALOR DA COMISSÃO | H1: COMISSÕES/CORRETORES
A2: 42150 | B2: 42157 | C2: EDSON COSTA | D2: 6X | E2: HDI | F2: 0.15 | G2: 222.25
A3: 42153 | B3: 42159 | C3: WILSON DE SOUZA | D3: 1X | E3: BRADESCO | F3: 0.17 | G3: 230.32
A4: 42163 | B4: 42163 | C4: ERIVALDO DOS SANTOS | D4: 4X | E4: BRADESCO | F4: 0.1 | G4: 293.84
A5: 42160 | B5: 42169 | C5: EMMANUEL MARTINS DE ALBUQUERQUE | D5: 1X | E5: TOKIO | F5: 0.1 | G5: 113.1
A6: 42164 | B6: 42167 | C6: JOSE GERALDO DE MOREIRA | D6: 4X | E6: AZUL | F6: 0.1 | G6: 126.88
A7: 42167 | B7: 42169 | C7: KELLY CRISTINA ACACIO VICENTE | D7: 4X | E7: BRADESCO | F7: 0.1 | G7: 290.29
A8: 42167 | B8: 42167 | C8: GABRIELA GONÇCALVES BRITO | D8: 3X | E8: AZUL | F8: 0.1 | G8: 99.68
A9: 42167 | B9: 42167 | C9: ERICA MARIA GOMES DE LIMA | D9: 5X | E9: SUL AMÉRICA | F9: 0.15 | G9: 256.66
A10: 42172 | B10: 42172 | C10: PAULO ALEXANDRE DA COSTA | D10: 6X | E10: MAPFRE | F10: 0.1 | G10: 112.75
A11: 42173 | B11: 42173 | C11: ERICA MARIA GOMES DE LIMA | D11: 10X | E11: MITSUI | F11: 0.25 | G11: 631.84
A12: 42167 | B12: 42165 | C12: FERNANDA MARTINS | D12: 10X | E12: MITSUI | F12: 0.1 | G12: 241.98
A13: 42174 | B13: 42174 | C13: RAFAEL FERREIRA (L200) | D13: 1X | E13: SUHAI | F13: 0.25 | G13: 690.7
... A23: 42184 | B23: 42188 | C23: FRANCISCO WESLEY ALVES ALMEIDA RUFINO | D23: 5X | E23: PORTO | F23: 0.25 | G23: 530.59
A24: VALOR TOTAL: | G24: =SUM(G2:G23) -> 5578.22

Sheet JULHO 2015
A1: DATA DA TRANS. | B1: VIGÊNCIA | C1: SEGURADO | D1: QNT. DE PARCELAS | E1: SEGURADORA | F1: % COMISSÃO | G1: VALOR DA COMISSÃO | H1: REPASSE COMISSÃO
A2: 42186 | B2: 42186 | C2: RENATO DE JESUS LINS | D2: 1X | E2: AZUL | F2: 0.1 | G2: 246.98
A3: 42188 | B3: 42188 | C3: CLAUDIA REGINA DIAS | D3: 7X | E3: PORTO | F3: 0.1 | G3: 101.07
A4: 42186 | B4: 42188 | C4: SUELI APARECIDA JORGE DE AZEVED0 | D4: 10X | E4: AZUL | F4: 0.2 | G4: 274.03
A5: 42191 | B5: 42194 | C5: RAIMUNDO NONATO NUNES | D5: 10X | E5: MITSUI | F5: 0.25 | G5: 384.93
A6: 42193 | B6: 42193 | C6: GESIMARA DA COSTA MENDES | D6: 5X | E6: MITSUI | F6: 0.1 | G6: 157.86
A7: 42193 | B7: 42193 | C7: MANUEL MAX FIRMINO LOPES FILHO | D7: 4X | E7: AZUL | F7: 0.18 | G7: 235.18
A8: 42195 | B8: 42192 | C8: ANSELMO DO SANTOS UGARTE | D8: 4X | E8: AZUL | F8: 0.1 | G8: 127.16
A9: 42195 | B9: 42195 | D9: 4X | E9: AZUL | F9: 0.1 | G9: 40.08
A10: 42195 | B10: 42196 | C10: SEGMAX TECNOLOGIA E M ARGAMASSAS LTDA | D10: 4X | E10: HDI | F10: 0.25 | G10: 381.25
A11: 42198 | B11: 42200 | C11: ANGELO MARCIO ALVES NEVES | D11: 4X | E11: AZUL | F11: 0.13 | G11: 162.94
A12: 42199 | B12: 42195 | C12: BRUNO SOUZA AGUIAR | D12: 1X | E12: AZUL | F12: 0.2 | G12: 273.78
A13: 42200 | B13: 42200 | C13: ROBERTO CELESTINO | D13: 5X | E13: SULAMERICA | F13: 0.15 | G13: 235.49
A14: 42201 | B14: 42201 | C14: THAIS FREITAS DOS SANTOS SOUZA | D14: 7X | E14: MITSUI | F14: 0.25 | G14: 431.61
A15: 42200 | B15: 42200 | C15: STAR PACK | D15: 5X | E15: SULAMERICA | F15: 0.1 | G15: 215.7
A16: 42202 | B16: 42204 | C16: NEUSA APARECIDA DE ARAUJO | D16: 5X | E16: SULAMERICA | F16: 0.25 | G16: 889.46
A17: 42202 | B17: 42202 | C17: REGIANI APARECIDA GARDELLI DEL BUSSO | D17: 10X | E17: AZUL | F17: 0.2 | G17: 207.53
A18: 42206 | B18: 42206 | D18: 1X | E18: PORTO | F18: 0.25 | G18: 55.49
A19: 42206 | B19: 42206 | D19: 5X | E19: PORTO | F19: 0.25 | G19: 215.35
A20: 42207 | B20: 42207 | C20: RAFAEL CUNHA DO NASCIMENTO | D20: 1X | E20: PORTO | F20: 0.25 | G20: 230.48
A21: 42207 | B21: 42207 | C21: FELIPE MOTA PENDEK | D21: 4X | E21: PORTO | F21: 0.1 | G21: 258.8
A22: 42209 | B22: 42210 | C22: EDIVALDO PEREIRA DA SILVA | D22: 4X | E22: TOKIO | F22: 0.2 | G22: 288.27
A23: 42209 | B23: 42209 | C23: IZAIAS MENDES DA SILVA | D23: 10X | E23: AZUL | F23: 0.1 | G23: 73.77
A24: 42212 | B24: 42209 | D24: 2X | E24: AZUL | F24: 0.1 | G24: 20.45
A25: 42213 | B25: 42213 | C25: MARIA LUISA NONATO MARTINES | D25: 10X | E25: AZUL | F25: 0.1 | G25: 175.87
A26: 42212 | B26: 42231 | C26: MAURICI AZEVEDO DO NASCIMENTO | D26: 5x | E26: PORTO | F26: 0.1 | G26: 211.02
A27: 42212 | B27: 42213 | C27: SERGIO RODRIGO BUENO | D27: 7X | E27: HDI | F27: 0.15 | G27: 302.08
A28: 42213 | B28: 42212 | C28: MARCIO DA CONCEIÇÃO DA COSTA | D28: 10X | E28: AZUL | F28: 0.15 | G28: 252.67
A29: 42212 | B29: 42212 | C29: LUIS VANTULIO DA COSTA | D29: 7X | E29: MITSUI | F29: 0.25 | G29: 352.89
A30: 42214 | B30: 42214 | C30: VALDEMIR SILVA DOS SANTOS | D30: 7X | E30: HDI | F30: 0.2 | G30: 343.47
A31: 42214 | B31: 42214 | D31: 1X | E31: AZUL | F31: 0.1 | G31: 11.84
A32: 42212 | B32: 42212 | D32: 8X | E32: AZUL | F32: 0.1 | G32: 52.66
A33: 42207 | B33: 42209 | C33: HELENILDA JOSEFA DA SILVA DE SOUSA | D33: 4X | E33: AZUL | F33: 0.25 | G33: 351.99 | H33: REPASSE JORGE = R4 175,99
A34: VALOR TOTAL: | G34: =SUM(G2:G33) -> 7562.15

Sheet AGOSTO 2016
A1: DATA DA TRANS. | B1: VIGÊNCIA | C1: SEGURADO | D1: QNT. DE PARCELAS | E1: SEGURADORA | F1: % COMISSÃO | G1: VALOR DA COMISSÃO | H1: REPASSE COMISSÃO
A2: 42222 | B2: 42222 | D2: 1X | E2: AZUL | F2: 0.1 | G2: 7.05
A3: 42223 | B3: 42226 | C3: EDIVALDO FRANCISCO SANTOS | D3: 4X | E3: HDI | F3: 0.1 | G3: 168.41
A4: 42223 | B4: 42226 | C4: MONIKA ELIZABETH JUNG MATRONI | D4: 4X | E4: BRADESCO | F4: 0.1 | G4: 165.29
A5: 42228 | B5: 42226 | C5: PEDRO PAULO FARIA | D5: 4X | E5: MITSUI | F5: 0.1 | G5: 94.72
A6: 42229 | B6: 42228 | C6: PAULO RAIMUNDO BAUEB | D6: 4X | E6: AZUL | F6: 0.1 | G6: 101.03
A7: 42230 | B7: 42236 | C7: MARCO AURELIO DA SILVA | D7: 4X | E7: AZUL | G7: 331.31
A8: 42230 | B8: 42231 | C8: VALDEMIR SILVA ALMEIDA | D8: 10X | E8: SUL AMÉRICA | F8: 0.1 | G8: 123.66
A9: 42237 | B9: 42237 | C9: EDUARDO TORRES DA CUNHA | D9: 1X | E9: TOKIO | F9: 0.1 | G9: 121.24
A10: 42230 | B10: 42230 | C10: WILLIAN ANTONIO GUEDES DOS SANTOS | D10: 4X | E10: AZUL | F10: 0.1 | G10: 346.57
A11: 42236 | B11: 42236 | C11: ROGERIO ORIOLI | D11: 5X | E11: SUL AMÉRICA | F11: 0.1 | G11: 124.32
A12: 42230 | B12: 42230 | C12: MARCOS ROBERTO ALENCAR SANTIAGO | D12: 4X | E12: AZUL | F12: 0.1 | G12: 179.34
A13: 42237 | B13: 42237 | C13: LEONARDO GABALDI CARDOSO | D13: 10X | E13: AZUL | F13: 0.1 | G13: 164.14
A14: 42240 | B14: 42606 | C14: ALCIDESIO CAETANO DA SILVA | D14: 4X | E14: AZUL | F14: 0.25 | G14: 585.65
A15: 42241 | B15: 42607 | C15: ROBERTA PRISCILA DA SILVA MATIAS | D15: 6X | E15: TOKIO | F15: 0.2 | G15: 235.94
A16: 42242 | B16: 42242 | C16: AQUINO IMÓVEIS | D16: 4X | E16: AZUL | F16: 0.1 | G16: 117.53
A17: 42243 | B17: 42244 | C17: LUCIANO DA SILVA SENA | D17: 8X | E17: PORTO | F17: 0.13 | G17: 253.94
A18: 42244 | B18: 42246 | C18: FRANCISCO ELEOTORIO CHAGAS JUNIOR | D18: 4X | E18: AZUL | F18: 0.15 | G18: 336.11
A19: 42244 | B19: 42250 | C19: LUCIENE TEREZA DA SILVA | D19: 4X | E19: AZUL | F19: 0.14 | G19: 198.25
A20: 42244 | B20: 42244 | C20: ALBERTO LINCOLN FERREIRA MALTA | D20: 4X | E20: AZUL | F20: 0.1 | G20: 122.15
A24: VALOR TOTAL: | G24: =SUM(G2:G23) -> 3776.65

Sheet SETEMBRO 2015
A1: DATA DA TRANS. | B1: VIGÊNCIA | C1: SEGURADO | D1: QNT. DE PARCELAS | E1: SEGURADORA | F1: % COMISSÃO | G1: VALOR DA COMISSÃO | H1: REPASSE COMISSÃO
A2: 42248 | B2: 42248 | C2: NEYRE MACIEL SEIXAS | D2: 3X | E2: SUHAI | F2: 0.2 | G2: 521.5
A3: 42248 | B3: 42260 | C3: LUCIANO DE LIMA DE ARAUJO | D3: 7X | E3: MITSUI | F3: 0.1 | G3: 78.49
A4: 42249 | B4: 42258 | C4: JEFFERSON RODRIGUES | D4: 4X | E4: BRADESC0 | F4: 0.15 | G4: 381
A5: 42257 | B5: 42257 | C5: SEGMAX | D5: 4X | E5: BRADESCO | F5: 0.19 | G5: 377.7
A6: 42257 | B6: 42258 | C6: MICHELLE DOS SANTOS SOUZA | D6: 4X | E6: HDI | F6: 0.2 | G6: 396.43
A7: 42257 | B7: 42262 | C7: ADJAILSON PONTES DA SILVA | D7: 4X | E7: BRADES | F7: 0.1 | G7: 239.58
A8: 42261 | B8: 42263 | C8: JOSÉ MILTON REIS | D8: 7X | E8: MITSUI | F8: 0.25 | G8: 312.45
C9: GILBERTO RODRIGUES MAGUETA | D9: 4x | E9: HDI | F9: 0.25 | G9: 231.99
C10: PAULO ROGERIO TEIXEIRA DA SILVA | D10: 4X | E10: AZUL | F10: 0.1 | G10: 90.42
C11: FRANCISCO DAS CHAGAS FERREIRA DE LIMA | D11: 4X | E11: SUL AMÉRICA | F11: 0.1 | G11: 524.72
A12: 42265 | B12: 42265 | C12: REGINA CRISTINA LEITE PEREIRA | D12: 4X | E12: SUL AMÉRICA | F12: 0.1 | G12: 92.94
A13: 42268 | B13: 42264 | C13: AKISHIDE YAMASHITA | D13: 1X | E13: PORTO | F13: 0.1 | G13: 110.7
A14: 42271 | B14: 42271 | C14: PAULA REGINA BOTARO | D14: 4X | E14: SUL AMÉRICA | F14: 0.1 | G14: 182.92
A15: 42271 | B15: 42268 | C15: RAFAEL BRAULIO ROCHA | D15: 4X | E15: AZUL | F15: 0.1 | G15: 158.32
A16: 42277 | B16: 42272 | C16: AREMI FARIAS DE MORAIS | D16: 10X | E16: AZUL | F16: 0.1 | G16: 178.58
A17: 42272 | B17: 42272 | C17: JAQUELINE HENRIQUE DOS SANTOS | D17: 3X | E17: SUHAI | F17: 0.2 | G17: 216.79
A18: 42272 | B18: 42276 | C18: JOSE ROGERIO MONTEIRO | D18: 4X | E18: AZUL | F18: 0.15 | G18: 172.15
A19: 42272 | B19: 42272 | C19: ENDOSSO - ANDREZA PATRICIA LOPES PONTES | D19: 4X | E19: SUL AMÉRICA | F19: 0.1 | G19: 173.68
A20: 42272 | B20: 42276 | C20: GENIVALDO ANTONIO DE OLIVEIRA | D20: 5x | E20: PORTO | F20: 0.1 | G20: 162.93
A21: 42272 | B21: 42272 | C21: LEANDRO ALMEIDA CRISPIM ME | D21: 6X | E21: TOKIO | F21: 0.1 | G21: 239.94
A22: 42277 | B22: 42277 | C22: THAIS FERRE FAILLA | D22: 4X | E22: AZUL | F22: 0.1 | G22: 117.78
A23: 42279 | B23: 42274 | C23: SEVERINO GOMES | D23: 4X | E23: AZUL | F23: 0.1 | G23: 112.12
A25: VALOR TOTAL: | G25: =SUM(G2:G24) -> 5073.13

Sheet OUTUBRO 2015
A1: DATA DA TRANS. | B1: VIGÊNCIA | C1: SEGURADO | D1: QNT. DE PARCELAS | E1: SEGURADORA | F1: % COMISSÃO | G1: VALOR DA COMISSÃO | H1: REPASSE COMISSÃO
A2: 42277 | B2: 42282 | C2: SUEMARY LOPES DE BARROS | D2: 4X | E2: AZUL | F2: 0.1 | G2: 111.39
A3: 42286 | B3: 42287 | C3: MARLUCE DOS SANTOS MARTINS | D3: 4X | E3: AZUL | F3: 0.2 | G3: 280.75
A4: 42286 | B4: 42288 | C4: ALEX GONÇALVES DE ANDRADE | D4: 4X | E4: AZUL | F4: 0.2 | G4: 313.7
A5: 42286 | B5: 42289 | C5: MARCOS LEANDRO DA SILVA | D5: 4X | E5: AZUL | F5: 0.2 | G5: 232.83
A6: 42286 | B6: 42291 | C6: JULIANA MAITAN BITTENCOURT | D6: 4X | E6: PORTO | F6: 0.1 | G6: 152.62
A7: 42283 | B7: 42283 | C7: F INICIATIVAS CONSULTORIA E ASS EMPRES LTDA | D7: 4X | E7: PORTO | F7: 0.22 | G7: 390.81 | H7: EMPRESARIAL
A8: 42298 | B8: 42298 | C8: PRISCILA MINGHETTI PERRUD | D8: 4X | E8: PORTO | F8: 0.16 | G8: 233.77
A9: 42303 | B9: 42303 | C9: WALTER PEREIRA DE ALMEIDA | D9: 10X | E9: PORTO | F9: 0.13 | G9: 166.96
A10: 42304 | B10: 42304 | C10: LUCIANO DA SILVA SENA | D10: 4X | E10: BRADESCO | F10: 0.15 | G10: 385.16
A11: 42304 | B11: 42308 | C11: PAULO JIRO NOMI | D11: 5X | E11: SUL AMÉRICA | F11: 0.1 | G11: 130.24
A12: 42304 | B12: 42304 | C12: MARIO PAULO DA SILVA DOMINGOS | D12: 6X | E12: BRADESCO | F12: 0.15 | G12: 844.13
A13: 42306 | B13: 42306 | C13: ARLETE FERREIRA PEREIRA | D13: 4X | E13: MITSUI | F13: 0.225 | G13: 324.16
A14: 42306 | B14: 42306 | C14: CLAUS WILLIAM SCHULZE | D14: 6X | E14: TOKIO | F14: 0.1 | G14: 79.71
A15: 42307 | B15: 42308 | C15: EDILENE ROSA DE ARAUJO | D15: 10X | E15: SUL AMÉRICA | F15: 0.1 | G15: 130.18
A16: 42307 | B16: 42311 | C16: LUANA DE CAIRES COELHO | D16: 4X | E16: HDI | F16: 0.15 | G16: 170.63
A25: VALOR TOTAL: | G25: =SUM(G2:G24) -> 3947.04

Sheet NOVEMBRO 2015
A1: DATA DA TRANS. | B1: VIGÊNCIA | C1: SEGURADO | D1: QNT. DE PARCELAS | E1: SEGURADORA | F1: % COMISSÃO | G1: VALOR DA COMISSÃO | H1: REPASSE COMISSÃO
B2: 42313 | C2: FERNANDA GONZALES DE LIMA | D2: 4X | E2: AZUL | F2: 0.2 | G2: 226.88
A3: 42311 | B3: 42311 | C3: WILLIAN ANTONIO GUEDES DOS SANTOS | D3: 6X | E3: BRADESCO | F3: 0.1 | G3: 323.94
A4: 42318 | B4: 42318 | C4: ALEX SANDRO BRAGATO | D4: 7X | E4: MITSUI | F4: 0.15 | G4: 205.86
B5: 42324 | C5: TARCISIO ANTONIO VALENTIN | D5: 1X | E5: PORTO | F5: 0.1 | G5: 132.56
A6: 42319 | B6: 42319 | C6: ADEMIR CYRINO GARCIA | D6: 4X | E6: AZUL | F6: 0.15 | G6: 178.04
A7: 42318 | B7: 42318 | C7: JANIO DUTRA DA SILVA | D7: 6X | E7: TOKIO | F7: 0.1 | G7: 183.3
A8: 42320 | B8: 42320 | C8: SEBASTIAO MARCIO CAPELLO | D8: 4X | E8: AZUL | F8: 0.2 | G8: 207.64
A9: 42320 | B9: 42320 | C9: ROSANA ARAKAKI GUIMARAES | D9: 5X | E9: PORTO | F9: 0.1 | G9: 333.35
A10: 42324 | B10: 42324 | C10: SEVERINO BERNARDO DA SILVA | D10: 4X | E10: AZUL | F10: 0.25 | G10: 233.59
A11: 42324 | B11: 42327 | C11: LUCIENE APARECIDA PANSARIN MEI | D11: 4X | E11: AZUL | F11: 0.25 | G11: 234.33
A12: 42324 | B12: 42327 | C12: JOSE AUGUSTO GALAN | D12: 2X | E12: AZUL | F12: 0.13 | G12: 142.6
A13: 42324 | B13: 42330 | C13: FLAVIA RUBIA DE PAULA | D13: 4X | E13: AZUL | F13: 0.1 | G13: 124.51
A14: 42327 | B14: 42333 | C14: ESTANISLAU SEVERINO DE ARRUDA JUNIOR | D14: 10X | E14: PORTO | F14: 0.2 | G14: 224.65
A15: 42327 | B15: 42327 | C15: IVONE ALVES DE MELO | D15: 4X | E15: AZUL | F15: 0.2 | G15: 330.33
A16: 42331 | B16: 42329 | C16: AILTON ROCHA GONÇALVES | D16: 1X | E16: AZUL | F16: 0.2 | G16: 396.39
A17: 42338 | B17: 42340 | C17: ORLANDO BERNARDES FAUSTINO | D17: 4X | E17: PORTO | F17: 0.15 | G17: 172.02
... A20: 42339 | B20: 42336 | C20: ERIKA DIAS LIMA | D20: 4X | E20: AZUL | F20: 0.1 | G20: 142.03
A24: VALOR TOTAL: | G24: =SUM(G2:G23) -> 4252.6

Sheet DEZEMBRO 2015
A1: DATA DA TRANS. | B1: VIGÊNCIA | C1: SEGURADO | D1: QNT. DE PARCELAS | E1: SEGURADORA | F1: % COMISSÃO | G1: VALOR DA COMISSÃO | H1: REPASSE COMISSÃO
A2: 42340 | B2: 42341 | C2: ALEXANDRA SEREICIKAS DE SOUSA LIMA | D2: 4X | E2: AZUL | F2: 0.15 | G2: 159.22
A3: 42340 | B3: 42342 | C3: DANIELA AVELINO CUNHA ANDRADE | D3: 1X | E3: HDI | F3: 0.15 | G3: 190.38
A4: 42347 | B4: 42347 | C4: ANA MARIA SOTERO LIMA | D4: 4X | E4: AZUL | F4: 0.1 | G4: 133.27
A5: 42352 | B5: 42352 | C5: GERSON FONSECA MENDES | D5: 4X | E5: ITAU | F5: 0.1 | G5: 186.59
A6: 42348 | B6: 42345 | C6: MARCIA ISABEL DOS SANTOS | D6: 10X | E6: PORTO | F6: 0.1 | G6: 218.56
A7: 42349 | B7: 41255 | C7: MARCELO PAULO DE OLIVEIRA | D7: 2X | E7: HDI | F7: 0.11 | G7: 258.5
A8: 42349 | B8: 42352 | C8: TEGNUS FRANCISCUS LAMAS | D8: 7X | E8: MITSUI | F8: 0.2 | G8: 312.28
A9: 42349 | B9: 42354 | C9: ALAOR GONÇALVES DIAS | D9: 5X | E9: PORTO | F9: 0.1 | G9: 167.57
A10: 42352 | B10: 42352 | C10: ESTANISLAU SEVERINO DE ARRUDA JUNIOR | D10: 4X | E10: AZUL | F10: 0.2 | G10: 190.52
A11: 42355 | B11: 42358 | C11: PAULO RAIMUNDO BAUEB | D11: 1X | E11: AZUL | F11: 0.1 | G11: 80.98
A12: 42353 | B12: 42353 | C12: SOLANGE ALMEIDA RODRIGUES | D12: 4X | E12: AZUL | F12: 0.2 | G12: 270.35 | H12: 135.17
A13: 42354 | B13: 42355 | C13: OSVALDO GONÇALVES DE ALMEIDA S | D13: 4X | E13: AZUL | F13: 0.1 | G13: 147.06
A14: 42354 | B14: 42355 | C14: ALEXANDRE ALFREDO LAMEIRÃO | D14: 4X | E14: AZUL | F14: 0.1 | G14: 133.99
A15: 42356 | B15: 42356 | C15: ROSANA ARAKAKI GUIMARAES | D15: 4X | E15: ITAU | F15: 0.23 | G15: 786.74
A16: 42360 | B16: 42361 | C16: SUELI GOMES DA SILVA JURAS | D16: 4X | E16: AZUL | F16: 0.2 | G16: 235.65
A17: 42359 | B17: 42356 | C17: RAFAEL CUNHA DO NASCIMENTO | D17: 10X | E17: AZUL | F17: 0.1 | G17: 189.85
A18: 42361 | B18: 42362 | C18: ABELARDO MATIAS BACELAR | D18: 5X | E18: SUL AMÉRICA | F18: 0.25 | G18: 397.6
A19: 42361 | B19: 42361 | C19: GERSON FONSECA MENDES | D19: 4X | E19: AZUL | F19: 0.1 | G19: 234.26
A20: 42361 | B20: 42361 | C20: MANOELINA MARIA MARTINS | D20: 4X | E20: AZUL | F20: 0.2 | G20: 306.52
A21: 42361 | B21: 42361 | C21: OSWALDO ANTONIO MENDES | D21: 4X | E21: AZUL | F21: 0.2 | G21: 272.19
A22: 42367 | B22: 42367 | C22: CAMILA APARECIDA DE LIMA | D22: 4X | E22: AZUL | F22: 0.15 | G22: 199.02
A23: 42368 | B23: 42368 | C23: ERIKA DIAS LIMA | D23: 4X | E23: HDI | F23: 0.1 | G23: 175.42
A24: 42361 | B24: 42374 | C24: ADRIANA M PEREIRA | D24: 1X | E24: AZUL | F24: 0.18 | G24: 278.89
A25: VALOR TOTAL: | G25: =SUM(G2:G24) -> 5525.41

Sheet JANEIRO 2016
A1: DATA DA TRANS. | B1: VIGÊNCIA | C1: SEGURADO | D1: QNT. DE PARCELAS | E1: SEGURADORA | F1: % COMISSÃO | G1: VALOR DA COMISSÃO | H1: REPASSE COMISSÃO | I1: CORRETOR
A2: 42374 | B2: 42377 | C2: ANTONIO CESAR ESTEVES | D2: 4X | E2: AZUL | F2: 0.25 | G2: 434.78 | H2: 217.39 | I2: JORGE
A3: 42374 | B3: 42378 | C3: KATIA REGINA DA SILVA | D3: 4X | E3: MITSUI | F3: 0.21 | G3: 257.13
A4: 42373 | B4: 42373 | C4: SERGIO MELLO RAMALHO DE CARVALHO | D4: 10X | E4: MAPFRE | F4: 0.1 | G4: 150.94 | H4: 75.47 | I4: MAURO
A5: 42383 | B5: 42381 | C5: ROSANA CLAUDIA FAUSTINO | D5: 4X | E5: AZUL | F5: 0.15 | G5: 219.47
A6: 42384 | B6: 42379 | C6: LUANA CARLA MARQUES | D6: 4X | E6: AZUL | F6: 0.1 | G6: 138.73
A7: 42377 | B7: 42378 | C7: CARLOS EDUARDO SILVA DE SOUZA | D7: 10X | E7: AZUL | F7: 0.15 | G7: 313.33
A8: 42381 | B8: 42381 | C8: CARLOS ALBERTO ROQUE DOS SANTOS | D8: 10X | E8: SUL AMÉRICA | F8: 0.25 | G8: 270.11
A9: 42387 | B9: 42385 | C9: WILLIAM MARCILIO RIBEIRO DA SILVA | D9: 10x | E9: AZUL | F9: 0.1 | G9: 260.82
A10: 42389 | B10: 42387 | C10: JEFFERSON D AMBROSIO DA CONCEIÇÃO | D10: 10X | E10: AZUL | F10: 0.1 | G10: 167.63
A11: 42396 | B11: 42396 | C11: REGIANE RHEIN TORRES SOBRAL | D11: 4X | E11: SUL AMÉRICA | F11: 0.1 | G11: 293.97
A12: 42391 | B12: 42391 | C12: GEANE SALVIANO TEPERINO AVILA | D12: 4X | E12: HDI | F12: 0.1 | G12: 145.47
A13: 42391 | B13: 42391 | C13: MIRIÃ CORREA PEREIRA ISRAEL | D13: 6X | E13: TOKIO | F13: 0.1 | G13: 181.98
A14: 42396 | B14: 42396 | C14: RONALDO TORRES SOBRAL | D14: 10X | E14: TOKIO | F14: 0.1 | G14: 498.9
A15: 42391 | B15: 42391 | C15: PAULO ROGERIO TEIXEIRA DA SILVA | D15: 6X | E15: MITSUI | F15: 0.1 | G15: 125.27
B16: 42398 | C16: FABIO FERNANDES COSTA | D16: 5X | E16: SUL AMÉRICA | F16: 0.1 | G16: 197.6
A17: 42397 | B17: 42397 | C17: GERSY ANTUNES DE ALMEIDA | D17: 9X | E17: TOKIO | F17: 0.15 | G17: 252.7
A18: VALOR TOTAL: | G18: =SUM(G2:G17) -> 3908.83 | H18: =SUM(H2:H17) -> 292.86

Sheet FEVEREIRO 2016
A1: DATA DA TRANS. | B1: VIGÊNCIA | C1: SEGURADO | D1: QNT. DE PARCELAS | E1: SEGURADORA | F1: % COMISSÃO | G1: VALOR DA COMISSÃO | H1: REPASSE COMISSÃO | I1: CORRETOR
A2: 42404 | B2: 42402 | C2: HUMBERTO MATIAS ALVES SILVA | D2: 4X | E2: PORTO | F2: 0.1 | G2: 203.91
A3: 42404 | B3: 42409 | C3: MARIA RISALVA TAVARES | D3: 4X | E3: AZUL | F3: 0.1 | G3: 217.61
A4: 42403 | B4: 42401 | C4: FRANCISCO JOSE MOREIRA | D4: 5X | E4: PORTO | F4: 0.1 | G4: 374.37
A5: 42417 | B5: 42417 | C5: MIRIAN RIBEIRO | D5: 8X | E5: SUL AMÉRICA | F5: 0.1 | G5: 187.16
A6: 42410 | B6: 42405 | C6: ADRINI CARLOS CORTEZ | D6: 3X | E6: AZUL | F6: 0.1 | G6: 138.13
A7: 42387 | B7: 42414 | C7: ELAINE CRISTINA DA SILVA | D7: 1X | E7: AZUL | F7: 0.1 | G7: 118.32
A8: 42412 | B8: 42413 | C8: MARIA APARECIDA ALVES NOGUEIRA | D8: 4X | E8: AZUL | F8: 0.1 | G8: 160.87
A9: 42415 | B9: 42414 | C9: MARIA APARECIDA DOMINGOS | D9: 4X | E9: AZUL | F9: 0.17 | G9: 234.19
A10: 42404 | B10: 42403 | C10: MARIA RISALVA TAVARES | D10: 4X | E10: AZUL | F10: 0.1 | G10: 217.61
B11: 42410 | C11: EMPRESARIAL IGREJA METODISTA | D11: 4X | E11: MARITIMA | F11: 0.25 | G11: 253.59
B12: 42411 | C12: NORBERTO DE SOUZA | D12: 6X | E12: MITSUI | F12: 0.1 | G12: 240.92
A13: 42410 | B13: 42412 | C13: LUCIANA APEZZATTO JOAQUIM UNGARELLO | D13: 6X | E13: TOKIO | F13: 0.1 | G13: 130.16
A14: 42417 | B14: 42417 | C14: MARCOS LEANDRO DA SILVA | D14: 4X | E14: HDI | F14: 0.15 | G14: 163.99
A15: 42419 | B15: 42419 | C15: ANTONIO SOARES DE CARVALHO | D15: 10X | E15: AZUL | F15: 0.1 | G15: 98.7
A16: 42422 | B16: 42422 | C16: ANGELA DOS SANTOS CARVALHO | D16: 4X | E16: AZUL | F16: 0.2 | G16: 364.66
A17: 42424 | B17: 42426 | C17: JOSE AMARO BATISTA | D17: 4X | E17: AZUL | F17: 0.15 | G17: 203.02
A18: 42424 | B18: 42424 | C18: ALISSON GONÇALVES DA SILVA | D18: 4X | E18: TOKIO | F18: 0.15 | G18: 343.52
A19: 42425 | B19: 42425 | C19: CELIA CLARICE DE MELO DEL CAMPO | D19: 6X | E19: MAPFRE | F19: 0.12 | G19: 141.93
B20: 42425 | C20: CRISLAINE VIEIRA RIBEIRO | D20: 10X | E20: AZUL | F20: 0.17 | G20: 126.93
A26: VALOR TOTAL: | G26: =SUM(G2:G25) -> 3919.59 | H26: =SUM(H2:H25) -> 0

Sheet MARÇO 2016
A1: DATA DA TRANS. | B1: VIGÊNCIA | C1: SEGURADO | D1: QNT. DE PARCELAS | E1: SEGURADORA | F1: % COMISSÃO | G1: VALOR DA COMISSÃO | H1: REPASSE COMISSÃO | I1: CORRETOR
A2: 42419 | B2: 42433 | C2: FABIO LUIS DO CARMO | D2: 4X | E2: AZUL | F2: 0.1 | G2: 156.73
A3: 42447 | B3: 42450 | C3: MARCIO DA SILVA CONCEIÇÃO CAVALCANTI | D3: 10X | E3: AZUL
A4: 42432 | B4: 42432 | C4: MARCELA DALTO AMMIRABILE | D4: 4X | E4: AZUL | F4: 0.1 | G4: 163.69
A5: 42443 | B5: 42443 | C5: ROBERTA GUACIRA DE SOUZA GOMES | D5: 4X | E5: AZUL | F5: 0.15 | G5: 208.63
A6: 42430 | B6: 42430 | C6: MONIKA ELISABETH JUNG MATRONI | D6: 4X | E6: AZUL | F6: 0.25 | G6: 390.44 | H6: 195.72 | I6: MAURO
A7: 42430 | B7: 42430 | C7: LUCIANA PIERONI COUTINHO | D7: 1X | E7: ITAÚ | F7: 0.1 | G7: 144.72
A8: 42438 | B8: 42438 | C8: JAILSON PEREIRA DA SILVA | D8: 4X | E8: PORTO | F8: 0.1 | G8: 262.46
A9: 42431 | B9: 42431 | C9: THIAGO TADEU DE LIMA | D9: 4X | E9: AZUL | F9: 0.1 | G9: 176.66
A10: 42435 | B10: 42435 | C10: EDSON BATISTA DE MORAES | D10: 7X | E10: AZUL | F10: 0.15 | G10: 244.63
A11: 42443 | B11: 42443 | C11: ADRIANA DA SILVA MONÇÃO BARROS | D11: 10X | E11: AZUL | F11: 0.23 | G11: 311.35
A12: 42433 | B12: 42433 | C12: JOHNNY GUIMARAES BISPO DIAS | D12: 2X | E12: AZUL | F12: 0.15 | G12: 128.95
A13: 42432 | B13: 42432 | C13: GISELE DOS SANTOS | D13: 4X | E13: HDI | F13: 0.1 | G13: 169.73
A14: 42444 | B14: 42444 | C14: VANDERLEI PEREIRA DE ALMEIDA | D14: 4X | E14: AZUL | F14: 0.2 | G14: 241.87
A15: 42443 | B15: 42443 | C15: JAILSON DE JESUS SANTOS | D15: 2X | E15: MITSUI | F15: 0.1 | G15: 125.78
A16: 42439 | B16: 42439 | C16: CARLOS ALBERTO PINTO | D16: 4X | E16: AZUL | F16: 0.1 | G16: 91.18
A17: 42437 | B17: 42437 | C17: PRISCILA MINGHETTI PERRUD | D17: 5X | E17: SUL AMÉRICA | F17: 0.2 | G17: 218.31
A18: 42436 | B18: 42436 | C18: MARCOS LEANDRO DA SILVA | D18: 4X | E18: AZUL | F18: 0.1 | G18: 133.19
B19: 42435 | C19: EDSON COSTA | D19: 4X | E19: AZUL | F19: 0.1 | G19: 104.1
B20: 42446 | C20: AQUINO IMOVEIS | D20: 4X | E20: ALLIANZ | F20: 0.1 | G20: 35.67
B21: 42450 | C21: JORGE LUIS DE MELO | D21: 4X | E21: AZUL | F21: 0.1 | G21: 138.65
B22: 42454 | C22: RENATA CARLA FAUSTINO DE MELO | D22: 4X | E22: AZUL | F22: 0.1 | G22: 191.62
B23: 42456 | C23: FLAVIA APARECIDA MORAIS MARTINS | D23: 6X | E23: MITSUI | F23: 0.1 | G23: 221.69
B24: 42451 | C24: CARLOS EDUARDO SILVA DE SOUZA | D24: 10X | E24: AZUL | F24: 0.1 | G24: 209.57
B25: 42445 | C25: SARA FERREIRA GUIMARAES | D25: 4X | E25: AZUL | F25: 0.1 | G25: 147
A26: 42456 | B26: 42457 | C26: ADRIANA ROCHA SOUTO GUZZI | D26: 5X | E26: PORTO | F26: 0.12 | G26: 233.26
A27: 42450 | B27: 42450 | C27: IGNACIO TOLOSA ITURRALDE NETO | D27: 4X | E27: PORTO | F27: 0.2 | G27: 358.82
B28: 42431 | C28: MIRIAN RIBEIRO | D28: 8X | E28: SUL AMÉRICA | F28: 0.1 | G28: 192.31
A29: VALOR TOTAL: | G29: =SUM(G2:G28) -> 5001.01 | H29: =SUM(H2:H28) -> 195.72

Sheet ABRIL 2016
A1: DATA DA TRANS. | B1: VIGÊNCIA | C1: SEGURADO | D1: QNT. DE PARCELAS | E1: SEGURADORA | F1: % COMISSÃO | G1: VALOR DA COMISSÃO | H1: REPASSE COMISSÃO | I1: CORRETOR
B2: 42845 | C2: POLYANA DE PAULA ALBUQUERQUE | D2: 4X | E2: HDI | F2: 0.1 | G2: 194.11
B3: 42837 | C3: ROGERIO SPAGIARI | D3: 10X | E3: ITAÚ | F3: 0.15 | G3: 114.01
A30: VALOR TOTAL: | G30: =SUM(G2:G29) -> 308.12 | H30: =SUM(H2:H29) -> 0

Sheet MAIO 2016
A1: DATA DA TRANS. | B1: VIGÊNCIA | C1: SEGURADO | D1: QNT. DE PARCELAS | E1: SEGURADORA | F1: % COMISSÃO | G1: VALOR DA COMISSÃO | H1: REPASSE COMISSÃO | I1: CORRETOR
B2: 42857 | C2: MARILOURDES ARAUJO LIMA NUNES | D2: 4X | E2: ITAÚ | F2: 0.1 | G2: 201.98
B3: 42860 | C3: ADILSON VENCESLAU BRAS | D3: 10X | E3: AZUL | F3: 0.1 | G3: 119.25
B4: 42861 | C4: FERNANDA DE CASSIA MAXIMINO DA COSTA- MULTICANAL | D4: 5X | E4: PORTO | F4: 0.1 | G4: 105.36
B5: 42864 | C5: MARCOS JOSE DA SILVA | D5: 4X | E5: AZUL | F5: 0.1 | G5: 92.87
B6: 42868 | C6: HUGO LIMA | D6: 4X | E6: AZUL | F6: 0.1 | G6: 105.99
B7: 14/05/2017 | C7: GEORGE DE OLIVIEIRA | D7: 1X | E7: PORTO | F7: 0.1 | G7: 178.17
B8: 42873 | C8: FRANCISCO ROLIM DE LIMA- MULTICANAL | D8: 1X | E8: PORTO | F8: 0.1 | G8: 63.52
B9: 42874 | C9: LEONARDO HENRIQUE MENDES- MULTICANAL | D9: 10X | E9: AZUL | F9: 0.25 | G9: 297.17
B10: 42875 | C10: EVANDRO VILARONGA RIOS | D10: 4X | E10: ITAÚ | F10: 0.25 | G10: 238.67
B11: 42879 | C11: FERNANDO ANTONIO DE OLIVEIRA | D11: 2X | E11: ITAÚ | F11: 0.15 | G11: 646.69
B12: 42879 | C12: ANA NAZARE ALCAIDE DOS SANTOS | D12: 4X | E12: BRADESCO | F12: 0.15 | G12: 178.99
B13: 42880 | C13: SEVERINO MIGUEL DA SILVA | D13: 8X | E13: AZUL | F13: 0.15 | G13: 244.9
B14: 42882 | C14: RODRIGO GONÇALVES DA SILVA | D14: 4X | E14: PORTO | F14: 0.22 | G14: 452.79
B15: 42884 | C15: UILSON GONÇALVES GUERRERO UNGARELLO | D15: 6X | E15: TOKIO | F15: 0.1 | G15: 187.77
B16: 42885 | C16: ERICA MARIA GOMES DE LIMA | D16: 4X | E16: AZUL | F16: 0.1 | G16: 219.98
A40: VALOR TOTAL: | G40: =SUM(G2:G39) -> 3334.1 | H40: =SUM(H11:H39) -> 0

Sheet JUNHO 2016
A1: DATA DA TRANS. | B1: VIGÊNCIA | C1: SEGURADO | D1: QNT. DE PARCELAS | E1: SEGURADORA | F1: % COMISSÃO | G1: VALOR DA COMISSÃO | H1: REPASSE COMISSÃO | I1: CORRETOR
B2: 42888 | C2: EDSON COSTA | D2: 4X | E2: HDI | F2: 0.1 | G2: 149.55
B3: 42889 | C3: ANDREZA PATRICIA LOPES PONTES | D3: 4X | E3: AZUL | F3: 0.1 | G3: 319.17
B4: 42890 | C4: WILSON DE SOUZA | D4: 4X | E4: AZUL | F4: 0.1 | G4: 128.67
B5: 42894 | C5: ERIVALDO DOS SANTOS | D5: 4X | E5: HDI | F5: 0.1 | G5: 220.19
B6: 42895 | C6: VALDIR PACHECO | D6: 10X | E6: ITAÚ | F6: 0.1 | G6: 83.06
B7: 42898 | C7: GABRIELA GONÇALVES BRITO | D7: 4X | E7: AZUL | F7: 0.1 | G7: 90.95
B8: 42898 | C8: JOSÉ GERALDO MOREIRA | D8: 3X | E8: MITSUI | F8: 0.15 | G8: 188.51
B9: 42898 | C9: ERICA MARIA GOMES DE LIMA | D9: 5X | E9: SUL AMÉRICA | F9: 0.1 | G9: 236.02
B10: 42900 | C10: EMMANUEL MARTINS DE ALBUQUERQUE | D10: 1X | E10: TOKIO | F10: 0.1 | G10: 107.72
B11: 42901 | C11: LUCIANO CARDOSO CARBONE- MULTI CANAL | D11: 4X | E11: PORTO | F11: 0.1 | G11: 100.07
B12: 42903 | C12: ERICA MARIA GOMES DE LIMA | D12: 6X | E12: MITSUI | F12: 0.2 | G12: 207.85
B13: 42906 | C13: CARLOS LOPES REY | D13: 4X | E13: AZUL | F13: 0.15 | G13: 101.45
... B17: 42910 | C17: NELSON NUNES DA SILVA | D17: 6X | E17: TOKIO | F17: 0.1 | G17: 137.3
A32: VALOR TOTAL: | G32: =SUM(G2:G31) -> 2358.8 | H32: =SUM(H2:H31) -> 0

Sheet JULHO 2016
A1: DATA DA TRANS. | B1: VIGÊNCIA | C1: SEGURADO | D1: QNT. DE PARCELAS | E1: SEGURADORA | F1: % COMISSÃO | G1: VALOR DA COMISSÃO | H1: REPASSE COMISSÃO | I1: CORRETOR
B2: 42917 | C2: RENATO DE JESUS LINS | D2: 1X | E2: AZUL | F2: 0.1 | G2: 174.52
B3: 42918 | C3: FRANCISCO WESLEY ALVES ALMEIDA RUFINO | D3: 5X | E3: PORTO | F3: 0.25 | G3: 346.85
B4: 42919 | C4: SUELI APARECIDA JORGE DE AEVEDO | D4: 4X | E4: AZUL | F4: 0.15 | G4: 220.43
B5: 42919 | C5: CLAUDIA REGINA DIAS | D5: 7X | E5: PORTO | F5: 11.76% | G5: 122.74
B6: 42921 | C6: FERNANDO SERGIO VIANA MACHADO | D6: 3X | E6: PORTO | F6: 0.1 | G6: 226.52
B7: 42923 | C7: GESIMARA DA COSTA MENDES | D7: 5X | E7: AZUL | F7: 0.15 | G7: 210.33
B8: 42923 | C8: ANSELMO DOS SANTOS UGARTE | D8: 10X | E8: AZUL | F8: 0.1 | G8: 112.29
B9: 42924 | C9: MATHEUS FONSECA DARDENGO BENTO | D9: 10X | E9: AZUL | F9: 0.1 | G9: 191.16
B10: 42924 | C10: MANOEL MAXIMINO LOPES FILHO | D10: 1X | E10: MITSUI | F10: 0.15 | G10: 181.9
B11: 42925 | C11: RAIMUNDO NONATO NUNES | D11: 6X | E11: MITSUI | F11: 0.2 | G11: 267.21
B12: 42927 | C12: SEGMAX | D12: 10X | E12: TOKIO | F12: 0.1 | G12: 282.86
B13: 42931 | C13: ANGELO MARIO ALVES NEVES | D13: 4X | E13: MITSUI | F13: 0.2 | G13: 213.77
B14: 42933 | C14: REGIANI APARECIDA GARDELLI DEL BUSSO | D14: 10X | E14: AZUL | F14: 0.15 | G14: 145.53
B15: 42931 | C15: ROBERTO CELESTINO DOS SANTOS | D15: 5X | E15: SUL AMÉRICA | F15: 0.1 | G15: 138.3
B16: 42931 | C16: DORIVAL MALHEIROS CARDOSO | D16: 4X | E16: SUL AMÉRICA | F16: 0.16 | G16: 456.05
B17: 42932 | C17: THAIS FREITAS DOS SANTOS SOUZA | D17: 6X | E17: MITSUI | F17: 0.2 | G17: 303.65
... B30: 42945 | C30: LEANDRO MAYCON SILVA- MULTI CANAL | D30: 4X | E30: ITAÚ | F30: 0.2 | G30: 387.76
A40: VALOR TOTAL: | G40: =SUM(G2:G39) -> 7116.54 | H40: =SUM(H2:H39) -> 0

Sheet AGOSTO 2016,
A1: DATA DA TRANS. | B1: VIGÊNCIA | C1: SEGURADO | D1: QNT. DE PARCELAS | E1: SEGURADORA | F1: % COMISSÃO | G1: VALOR DA COMISSÃO | H1: REPASSE COMISSÃO | I1: CORRETOR
B2: 42968 | C2: EDUARDO TORRES DA CUNHA | D2: 6X | E2: TOKIO | F2: 0.1 | G2: 107.98
B3: 42967 | C3: MARCO AURELIO DA SILVA | D3: 4x | E3: AZUL | F3: 0.25 | G3: 295.31
B4: 42964 | C4: MARTHA MARIA PEREIRA DE JESUS | D4: 6X | E4: TOKIO | F4: 0.17 | G4: 390.85
B5: 42961 | C5: MARCO ROBERTO ALENCAR SANTIAGO | D5: 4X | E5: AZUL | F5: 0.1 | G5: 149.09
B6: 42962 | C6: MAURICI AZEVEDO DO NASCIMENTO | D6: 4X | E6: PORTO | F6: 0.1 | G6: 338.58
B7: 42959 | C7: PAULO RAIMUNDO BAUEB | D7: 4X | E7: AZUL | F7: 0.1 | G7: 88.74
B8: 42956 | C8: PEDRO PAULA FARIA | D8: 4X | E8: AZUL | F8: 0.1 | G8: 87.02
B9: 42962 | C9: VALDEMIR SILVA ALMEIDA | D9: 10X | E9: AZUL | F9: 0.2 | G9: 224.9
B10: 42975 | C10: ALBERTO LINCOLN FERREIRA MALTA | D10: 4X | E10: AZUL | F10: 0.1 | G10: 138.31
B11: 42972 | C11: ROBERTA PRISCILA DA SILVA MARTINS | D11: 6X | E11: TOKIO | F11: 0.1 | G11: 91.09
B12: 42973 | C12: KELLY CRISTINA ACACIO VICENTE | D12: 5X | E12: SUL AMERICA | F12: 0.1 | G12: 144.31
B13: 42971 | C13: ALCIDESIO CAETANO DA SILVA | D13: 4X | E13: AZUL | F13: 0.2 | G13: 417.5
... B15: 42973 | C15: AQUINO EMPREENDIMENTOS | D15: 4X | E15: AZUL | F15: 0.1 | G15: 101.04
A37: VALOR TOTAL: | G37: =SUM(G2:G36) -> 2880.13 | H37: =SUM(H2:H36) -> 0

Sheet SETEMBRO 2016
A1: DATA DA TRANS. | B1: VIGÊNCIA | C1: SEGURADO | D1: QNT. DE PARCELAS | E1: SEGURADORA | F1: % COMISSÃO | G1: VALOR DA COMISSÃO | H1: REPASSE COMISSÃO | I1: CORRETOR
B2: 42979 | C2: NEYRE MACIEL SEIXAS | D2: 3X | E2: SUHAI | F2: 0.17 | G2: 411.9
B3: 42981 | C3: LUCIENE TEREZA DA SILVA | D3: 5x | E3: AZUL | F3: 0.1 | G3: 150.52
B4: 42982 | C4: JEFFERSON RODRIGUES | D4: 4X | E4: BRADESCO | F4: 0.15 | G4: 359.6
B5: 42993 | C5: ADJAILSON PONTES DA SILVA | D5: 4X | E5: HDI | F5: 0.1 | G5: 246.61
B6: 42988 | C6: SEGMAX TECNOLOGIA EM ARGAMASSSAS LTDA | D6: 4X | E6: BRADESCO | F6: 0.2 | G6: 382.13
B7: 42999 | C7: RAFAEL BRAULIO ROCHA | D7: 4X | E7: AZUL | F7: 0.1 | G7: 133.5
B8: 42986 | C8: RICARDO BENEDITO CALAIS JESUS | D8: 4X | E8: SOMPO | F8: 0.17 | G8: 128.55
B9: 42993 | C9: GENI APARECIDA DE OLIVEIRA | D9: 4X | E9: AZUL | F9: 0.19 | G9: 183.92
B10: 42993 | C10: JOSÉ MILTON REIS | D10: 1X | E10: MITSUI | F10: 0.25 | G10: 305.15 | I10: JEFFERSON
B11: 42990 | C11: LUCIANO DE LIMA ARAUJO | D11: 6X | E11: MITSUI | F11: 0.15 | G11: 117.66
B12: 43007 | C12: JOSÉ ROGEIRO MONTEIRO | D12: 4X | E12: AZUL | F12: 0.15 | G12: 169.36
B13: 42992 | C13: PAULO ROGERIO TEIXEIRA | D13: 4X | E13: AZUL | F13: 0.1 | G13: 88.5
B14: 42992 | C14: RONALDO TORRES SOBRAL | D14: 4X | E14: SUHAI | F14: 0.25 | G14: 683.18
B15: 42994 | C15: CONDOMINIO VILLAGGIO DE PANAMBY | D15: 4X | E15: BRADESCO | F15: 0.1 | G15: 204.78
B16: 42997 | C16: GILBERTO RODRIGUES MAGUETA | D16: 4X | E16: AZUL | F16: 0.25 | G16: 226.15
B17: 43002 | C17: PAULA REGINA BOTARO | D17: 6X | E17: SUL AMERICA | F17: 0.1 | G17: 182.21
B18: 43007 | C18: GENIVALDO ANTONIO DE OLIVEIRA | D18: 5X | E18: AZUL | F18: 0.1 | G18: 162.91
B19: 42999 | C19: JAQUELINE HENRIQUE SANTIAGO DOS SANTOS | D19: 4X | E19: AZUL | F19: 0.25 | G19: 325.81
B20: 43004 | C20: LEANDRO DE ALMEIDA CRISPIM ME | D20: 6X | E20: TOKIO | F20: 0.1 | G20: 249.03
B21: 43005 | C21: SEVERINO GOMES | D21: 4X | E21: AZUL | F21: 0.15 | G21: 167.8
B22: 43008 | C22: THAIS FERRE FAILA | D22: 4x | E22: AZUL | F22: 0.1 | G22: 149.53
... B25: 43008 | C25: REGIANE RHEIN TORRES SOBRAL | D25: 3X | E25: SUHAI | F25: 0.1 | G25: 183.37
A40: VALOR TOTAL: | G40: =SUM(G2:G39) -> 5544.05 | H40: =SUM(H2:H39) -> 0

Sheet OUTUBRO 2016
A1: DATA DA TRANS. | B1: VIGÊNCIA | C1: SEGURADO | D1: QNT. DE PARCELAS | E1: SEGURADORA | F1: % COMISSÃO | G1: VALOR DA COMISSÃO | H1: REPASSE COMISSÃO | I1: CORRETOR
B2: 43009 | C2: FRANCISCO DAS CHAGAS FERREIRA DE LIMA | D2: 5X | E2: SUL AMERICA | F2: 0.1 | G2: 509.04
B3: 43011 | C3: MARIA MARGARIDA DA SILVA | D3: 4X | E3: HDI | F3: 0.1 | G3: 164.32
B4: 43013 | C4: SUEMARY LOPES DE BARROS | D4: 4X | E4: AZUL | F4: 0.1 | G4: 109.17
B5: 43013 | C5: JEFFERSON DE AMBROSIO DA CONCEIÇÃO | D5: 12X | E5: SUHAI | F5: 0.2 | G5: 317.91
B6: 43018 | C6: MARLUCE DOS SANTOS MARTINS | D6: 3X | E6: AZUL | F6: 0.15 | G6: 230.16
B7: 43020 | C7: MARCOS LEANDRO DA SILVA | D7: 4X | E7: AZUL | F7: 0.2 | G7: 243.38
B8: 43018 | C8: REGINA CRISTINA LEITE PEREIRA | D8: 3X | E8: SUL AMERICA | F8: 0.1 | G8: 92.79
B9: 43019 | C9: ALEX GONÇALVES DE ANDRADE | D9: 4X | E9: AZUL | F9: 0.15 | G9: 242.73
B10: 43021 | C10: NEUSA APARECIDA DE ARAUJO | D10: 4x | E10: SOMPO | F10: 0.1 | G10: 184.06 | H10: 92.03 | I10: CARLINHOS
B11: 43027 | C11: ADJAILSON PONTES DA SILVA | D11: 12X | E11: PORTO RASTR | F11: TAXA ÚNICA | G11: 150
B12: 43030 | C12: ANNA CLAUDIA ARENA SIQUEIRA DIAS | D12: 4X | E12: AZUL | F12: 0.1 | G12: 108.66
B13: 43022 | C13: JULIANA MAITAN BITTENCOURT | D13: 4X | E13: PORTO | F13: 0.15 | G13: 266.2
B14: 43030 | C14: JOSE DERNIVAL DOS SANTOS FILHO | D14: 8X | E14: BRADESCO | F14: 0.1 | G14: 161.97
B15: 43029 | C15: FRANCISCO GOMES NETO | D15: 10X | E15: PORTO | F15: 0.1 | G15: 218.11
B16: 43034 | C16: WALTER PEREIRA DE ALMEIDA | D16: 10X | E16: AZUL | F16: 0.25 | G16: 351.51
B17: 43033 | C17: JANIO DUTRA DA SILVA | D17: 10X | E17: SUHAI | F17: 0.1 | G17: 120.6
B18: 43036 | C18: ARLETE FERREIRA LIMA | D18: 6X | E18: MITSUI | F18: 0.225 | G18: 323.75
B19: 43037 | C19: CLAUS WILLIAM SHULZE | D19: 6X | E19: TOKIO | F19: 0.13 | G19: 102.85
B20: 43039 | C20: ARNALDO FARIAS FILHO | D20: 6X | E20: TOKIO | F20: 0.1 | G20: 126.53
B21: 43039 | C21: EDILENE ROSA DE ARAUJO | D21: 10X | E21: SUL AMERICA | F21: 0.13 | G21: 172.47
B22: 43036 | C22: CAIO BRUNO BATALZAR | D22: 12X | E22: PORTO RASTR | F22: TAXA ÚNICA | G22: 150
A39: VALOR TOTAL: | G39: =SUM(G2:G38) -> 4346.21 | H39: =SUM(H2:H38) -> 92.03

Sheet NOVEMBRO 2016
A1: DATA DA TRANS. | B1: VIGÊNCIA | C1: SEGURADO | D1: QNT. DE PARCELAS | E1: SEGURADORA | F1: % COMISSÃO | G1: VALOR DA COMISSÃO | H1: REPASSE COMISSÃO | I1: CORRETOR
B2: 43055 | C2: TARCISIO ANTONIO VALENTIM | D2: 1X | E2: PORTO | F2: 0.1 | G2: 143.03
B3: 43044 | C3: FERNANDA GONZALES DE LIMA | D3: 6X | E3: MITSUI | F3: 0.25 | G3: 333.43
B4: 43050 | C4: ADEMIR CYRINO GARCIA | D4: 4X | E4: AZUL | F4: 0.15 | G4: 177.05
B5: 43051 | C5: WILLIAN ANTONIO DE GUEDES | D5: 6X | E5: BRADESCO | F5: 0.1 | G5: 337.48
B6: 43049 | C6: ALEX SANDRO BRAGATO | D6: 6X | E6: MITSUI | F6: 0.1 | G6: 184.97
B7: 43051 | C7: SEBASTIAO MARCIO CAPELO | D7: 4X | E7: AZUL | F7: 0.21 | G7: 195.27
B8: 09/11/2017 | C8: ANDREZA PATRICIA LOPES PONTES | D8: 4X | E8: AZUL | F8: 0.1 | G8: 405.42
B9: 43046 | C9: ROSANA ARAKAKI GUIMARAES | D9: 5X | E9: PORTO | F9: 0.1 | G9: 333.35
B10: 43050 | C10: MARIA TOSHIKO OKADA | D10: 4X | E10: AZUL | F10: 0.13 | G10: 150.63
B11: 43061 | C11: FLAVIA RUBIA DE PAULA | D11: 4X | E11: AZUL | F11: 0.1 | G11: 146.08
B12: 43055 | C12: ANDERSON CLAYTON DA SILVA | D12: 12X | E12: ITURAN | F12: TAXA ÚNICA | G12: 300
B13: 43060 | C13: AILTON ROCHA GONÇALVES | D13: 2X | E13: AZUL | F13: 0.155 | G13: 320.07
B14: 43058 | C14: LUCIENE APARECIDA PANSARIN MEIRELES | D14: 4X | E14: AZUL | F14: 0.1 | G14: 115.71
B15: 43055 | C15: SEVERINO BERNARDO DA SILVA | D15: 4X | E15: AZUL | F15: 0.2 | G15: 185.4
B16: 43063 | C16: ENOQUE RAIMUNDO DE OLIVEIRA | D16: 4X | E16: AZUL | F16: 0.16 | G16: 125.32
B17: 43064 | C17: ESTANILAU SEVERINO DE ARRUDA JUNIOR | D17: 4X | E17: PORTO | F17: 0.1 | G17: 116.79
B18: 43065 | C18: ERIKA DIAS LIMA | D18: 4X | E18: AZUL | F18: 0.1 | G18: 148.47
